Workbook

Sheet report
A1: № | B1: Наименование | C1: Регистрационный номер | D1: Возраст компании, лет | E1: Вид деятельности/отрасль | F1: 2020, Налог на прибыль, RUB | G1: 2021, Налог на прибыль, RUB | H1: 2022, Налог на прибыль, RUB | I1: 2023, Налог на прибыль, RUB | J1: 2024, Налог на прибыль, RUB | K1: 2020, НДС, RUB | L1: 2021, НДС, RUB | M1: 2022, НДС, RUB | N1: 2023, НДС, RUB | O1: 2024, НДС, RUB | P1: 2020, Основные средства , RUB | Q1: 2021, Основные средства , RUB | R1: 2022, Основные средства , RUB | S1: 2023, Основные средства , RUB | T1: 2024, Основные средства , RUB | U1: 2020, Доходные вложения в материальные ценности, RUB | V1: 2021, Доходные вложения в материальные ценности, RUB | W1: 2022, Доходные вложения в материальные ценности, RUB | X1: 2023, Доходные вложения в материальные ценности, RUB | Y1: 2024, Доходные вложения в материальные ценности, RUB | Z1: 2020, Долгосрочные финансовые вложения, RUB | AA1: 2021, Долгосрочные финансовые вложения, RUB | AB1: 2022, Долгосрочные финансовые вложения, RUB | AC1: 2023, Долгосрочные финансовые вложения, RUB | AD1: 2024, Долгосрочные финансовые вложения, RUB | AE1: 2020, Прочие внеоборотные активы, RUB | AF1: 2021, Прочие внеоборотные активы, RUB | AG1: 2022, Прочие внеоборотные активы, RUB | AH1: 2023, Прочие внеоборотные активы, RUB | AI1: 2024, Прочие внеоборотные активы, RUB | AJ1: 2020, Внеоборотные активы, RUB | AK1: 2021, Внеоборотные активы, RUB | AL1: 2022, Внеоборотные активы, RUB | AM1: 2023, Внеоборотные активы, RUB | AN1: 2024, Внеоборотные активы, RUB | AO1: 2020, Запасы, RUB | AP1: 2021, Запасы, RUB | AQ1: 2022, Запасы, RUB | AR1: 2023, Запасы, RUB | AS1: 2024, Запасы, RUB | AT1: 2020, Дебиторская задолженность, RUB | AU1: 2021, Дебиторская задолженность, RUB | AV1: 2022, Дебиторская задолженность, RUB | AW1: 2023, Дебиторская задолженность, RUB | AX1: 2024, Дебиторская задолженность, RUB | AY1: 2020, Краткосрочные финансовые вложения, RUB | AZ1: 2021, Краткосрочные финансовые вложения, RUB | BA1: 2022, Краткосрочные финансовые вложения, RUB | BB1: 2023, Краткосрочные финансовые вложения, RUB | BC1: 2024, Краткосрочные финансовые вложения, RUB | BD1: 2020, Денежные средства и денежные эквиваленты, RUB | BE1: 2021, Денежные средства и денежные эквиваленты, RUB | BF1: 2022, Денежные средства и денежные эквиваленты, RUB | BG1: 2023, Денежные средства и денежные эквиваленты, RUB | BH1: 2024, Денежные средства и денежные эквиваленты, RUB | BI1: 2020, Прочие оборотные активы, RUB | BJ1: 2021, Прочие оборотные активы, RUB | BK1: 2022, Прочие оборотные активы, RUB | BL1: 2023, Прочие оборотные активы, RUB | BM1: 2024, Прочие оборотные активы, RUB | BN1: 2020, Оборотные активы, RUB | BO1: 2021, Оборотные активы, RUB | BP1: 2022, Оборотные активы, RUB | BQ1: 2023, Оборотные активы, RUB | BR1: 2024, Оборотные активы, RUB | BS1: 2020, Активы всего, RUB | BT1: 2021, Активы всего, RUB | BU1: 2022, Активы всего, RUB | BV1: 2023, Активы всего, RUB | BW1: 2024, Активы всего, RUB | BX1: 2020, Уставный капитал , RUB | BY1: 2021, Уставный капитал , RUB | BZ1: 2022, Уставный капитал , RUB | CA1: 2023, Уставный капитал , RUB | CB1: 2024, Уставный капитал , RUB | CC1: 2020, Переоценка внеоборотных активов, RUB | CD1: 2021, Переоценка внеоборотных активов, RUB | CE1: 2022, Переоценка внеоборотных активов, RUB | CF1: 2023, Переоценка внеоборотных активов, RUB | CG1: 2024, Переоценка внеоборотных активов, RUB | CH1: 2020, Нераспределенная прибыль (непокрытый убыток), RUB | CI1: 2021, Нераспределенная прибыль (непокрытый убыток), RUB | CJ1: 2022, Нераспределенная прибыль (непокрытый убыток), RUB | CK1: 2023, Нераспределенная прибыль (непокрытый убыток), RUB | CL1: 2024, Нераспределенная прибыль (непокрытый убыток), RUB | CM1: 2020, Капитал и резервы, RUB | CN1: 2021, Капитал и резервы, RUB | CO1: 2022, Капитал и резервы, RUB | CP1: 2023, Капитал и резервы, RUB | CQ1: 2024, Капитал и резервы, RUB | CR1: 2020, Заёмные средства (долгосрочные), RUB | CS1: 2021, Заёмные средства (долгосрочные), RUB | CT1: 2022, Заёмные средства (долгосрочные), RUB | CU1: 2023, Заёмные средства (долгосрочные), RUB | CV1: 2024, Заёмные средства (долгосрочные), RUB | CW1: 2020, Прочие долгосрочные обязательства, RUB | CX1: 2021, Прочие долгосрочные обязательства, RUB | CY1: 2022, Прочие долгосрочные обязательства, RUB | CZ1: 2023, Прочие долгосрочные обязательства, RUB | DA1: 2024, Прочие долгосрочные обязательства, RUB | DB1: 2020, Долгосрочные обязательства, RUB | DC1: 2021, Долгосрочные обязательства, RUB | DD1: 2022, Долгосрочные обязательства, RUB | DE1: 2023, Долгосрочные обязательства, RUB | DF1: 2024, Долгосрочные обязательства, RUB | DG1: 2020, Заёмные средства (краткосрочные), RUB | DH1: 2021, Заёмные средства (краткосрочные), RUB | DI1: 2022, Заёмные средства (краткосрочные), RUB | DJ1: 2023, Заёмные средства (краткосрочные), RUB | DK1: 2024, Заёмные средства (краткосрочные), RUB | DL1: 2020, Кредиторская задолженность, RUB | DM1: 2021, Кредиторская задолженность, RUB | DN1: 2022, Кредиторская задолженность, RUB | DO1: 2023, Кредиторская задолженность, RUB | DP1: 2024, Кредиторская задолженность, RUB | DQ1: 2020, Доходы будущих периодов , RUB | DR1: 2021, Доходы будущих периодов , RUB | DS1: 2022, Доходы будущих периодов , RUB | DT1: 2023, Доходы будущих периодов , RUB | DU1: 2024, Доходы будущих периодов , RUB | DV1: 2020, Прочие краткосрочные обязательства, RUB | DW1: 2021, Прочие краткосрочные обязательства, RUB | DX1: 2022, Прочие краткосрочные обязательства, RUB | DY1: 2023, Прочие краткосрочные обязательства, RUB | DZ1: 2024, Прочие краткосрочные обязательства, RUB | EA1: 2020, Краткосрочные обязательства, RUB | EB1: 2021, Краткосрочные обязательства, RUB | EC1: 2022, Краткосрочные обязательства, RUB | ED1: 2023, Краткосрочные обязательства, RUB | EE1: 2024, Краткосрочные обязательства, RUB | EF1: 2020, Выручка, RUB | EG1: 2021, Выручка, RUB | EH1: 2022, Выручка, RUB | EI1: 2023, Выручка, RUB | EJ1: 2024, Выручка, RUB | EK1: 2020, Себестоимость продаж, RUB | EL1: 2021, Себестоимость продаж, RUB | EM1: 2022, Себестоимость продаж, RUB | EN1: 2023, Себестоимость продаж, RUB | EO1: 2024, Себестоимость продаж, RUB | EP1: 2020, Коммерческие расходы, RUB | EQ1: 2021, Коммерческие расходы, RUB | ER1: 2022, Коммерческие расходы, RUB | ES1: 2023, Коммерческие расходы, RUB | ET1: 2024, Коммерческие расходы, RUB | EU1: 2020, Управленческие расходы, RUB | EV1: 2021, Управленческие расходы, RUB | EW1: 2022, Управленческие расходы, RUB | EX1: 2023, Управленческие расходы, RUB | EY1: 2024, Управленческие расходы, RUB | EZ1: 2020, Доходы от участия в других организациях, RUB | FA1: 2021, Доходы от участия в других организациях, RUB | FB1: 2022, Доходы от участия в других организациях, RUB | FC1: 2023, Доходы от участия в других организациях, RUB | FD1: 2024, Доходы от участия в других организациях, RUB | FE1: 2020, Проценты к получению, RUB | FF1: 2021, Проценты к получению, RUB | FG1: 2022, Проценты к получению, RUB | FH1: 2023, Проценты к получению, RUB | FI1: 2024, Проценты к получению, RUB | FJ1: 2020, Проценты к уплате, RUB | FK1: 2021, Проценты к уплате, RUB | FL1: 2022, Проценты к уплате, RUB | FM1: 2023, Проценты к уплате, RUB | FN1: 2024, Проценты к уплате, RUB | FO1: 2020, Прочие доходы, RUB | FP1: 2021, Прочие доходы, RUB | FQ1: 2022, Прочие доходы, RUB | FR1: 2023, Прочие доходы, RUB | FS1: 2024, Прочие доходы, RUB | FT1: 2020, Прочие расходы, RUB | FU1: 2021, Прочие расходы, RUB | FV1: 2022, Прочие расходы, RUB | FW1: 2023, Прочие расходы, RUB | FX1: 2024, Прочие расходы, RUB | FY1: 2020, Налог на прибыль, RUB | FZ1: 2021, Налог на прибыль, RUB | GA1: 2022, Налог на прибыль, RUB | GB1: 2023, Налог на прибыль, RUB | GC1: 2024, Налог на прибыль, RUB | GD1: 2020, Чистая прибыль (убыток), RUB | GE1: 2021, Чистая прибыль (убыток), RUB | GF1: 2022, Чистая прибыль (убыток), RUB | GG1: 2023, Чистая прибыль (убыток), RUB | GH1: 2024, Чистая прибыль (убыток), RUB
A2: 1 | B2: 2-ПУ УРАЛХИММОНТАЖ, АО | C2: 1045900831745 | D2: 29 | E2: Деятельность агентов по оптовой торговле строительными материалами | G2: 4031193 | K2: 4881 | L2: 4166663 | P2: 22272000 | AJ2: 44886000 | AO2: 417794000 | AT2: 95009000 | AU2: 125140000 | AV2: 83551000 | AW2: 83551000 | AX2: 39051000 | BD2: 15538000 | BE2: 14552000 | BF2: 9969000 | BG2: 8556000 | BH2: 6402000 | BN2: 528365000 | BO2: 139692000 | BP2: 93520000 | BQ2: 92107000 | BR2: 45453000 | BS2: 573251000 | BT2: 139692000 | BU2: 93520000 | BV2: 92107000 | BW2: 45453000 | BX2: 244000 | BY2: 244000 | BZ2: 244000 | CA2: 244000 | CB2: 244000 | CC2: 3011000 | CD2: 3011000 | CE2: 3011000 | CF2: 3011000 | CG2: 3011000 | CH2: -179987000 | CI2: -137724000 | CJ2: -139396000 | CK2: -139396000 | CL2: -139396000 | CM2: -176720000 | CN2: -134457000 | CO2: -136129000 | CP2: -136129000 | CQ2: -136129000 | DB2: 419000 | DG2: 3188000 | DL2: 743965000 | DM2: 271750000 | DN2: 227250000 | DO2: 225837000 | DP2: 179183000 | EA2: 749552000 | EB2: 274149000 | EC2: 229649000 | ED2: 228236000 | EE2: 181582000 | EF2: 498000 | EK2: 2091000 | EU2: 2395000 | FO2: 12224000 | FT2: 1980000 | FU2: 1621000 | FV2: 1672000 | FY2: -1722000 | GD2: 4490000 | GE2: -1621000 | GF2: -1672000
A3: 2 | B3: 529 ВСУ, ОАО | C3: 1090506000430 | D3: 31 | E3: Строительство жилых и нежилых зданий
A4: 3 | B4: АГКА-2, ООО | C4: 1115904013884 | D4: 14 | E4: Строительство жилых и нежилых зданий | F4: 6366 | G4: 2953 | K4: 509957 | L4: 275016 | AT4: 13129000 | BD4: 214000 | BN4: 13343000 | BS4: 13343000 | BX4: 10000 | CH4: 10654000 | CM4: 10664000 | DL4: 2679000 | EA4: 2679000 | EF4: 12939000 | EK4: 7399000 | FY4: -1108000 | GD4: 4432000
A5: 4 | B5: АГРОСЕПЫЧ, ООО | C5: 1095933000404 | D5: 16 | E5: Разведение молочного крупного рогатого скота, производство сырого молока | K5: 1871915 | L5: 837696 | M5: 474043 | N5: 557558 | P5: 145248000 | Q5: 139450000 | R5: 39450000 | S5: 37369000 | T5: 1729000 | AE5: 395000 | AJ5: 145643000 | AK5: 139450000 | AL5: 39450000 | AM5: 37369000 | AN5: 1729000 | AO5: 97044000 | AP5: 86265000 | AQ5: 37090000 | AR5: 20135000 | AT5: 52891000 | AU5: 6886000 | AV5: 4250000 | AW5: 4058000 | AZ5: 90000 | BD5: 129000 | BE5: 4897000 | BF5: 39000 | BI5: 23000 | BN5: 150207000 | BO5: 98138000 | BP5: 41379000 | BQ5: 24193000 | BS5: 295850000 | BT5: 237588000 | BU5: 80829000 | BV5: 61562000 | BW5: 1729000 | BX5: 1730000 | BY5: 1730000 | BZ5: 1730000 | CA5: 1730000 | CB5: 1729000 | CC5: 10000 | CD5: 10000 | CE5: 10000 | CF5: 10000 | CH5: 40964000 | CI5: 38451000 | CJ5: 35389000 | CK5: 33294000 | CM5: 88692000 | CN5: 86179000 | CO5: 63117000 | CP5: 61022000 | CQ5: 1729000 | CR5: 2409000 | CS5: 1509000 | CT5: 1509000 | DB5: 2409000 | DC5: 1509000 | DD5: 1509000 | DG5: 63168000 | DH5: 63934000 | DI5: 13934000 | DL5: 115901000 | DM5: 63954000 | DN5: 257000 | DO5: 540000 | DQ5: 25680000 | DR5: 22012000 | DS5: 2012000 | EA5: 204749000 | EB5: 149900000 | EC5: 16203000 | ED5: 540000 | EF5: 142462000 | EG5: 127106000 | EH5: 73187000 | EI5: 27932000 | EK5: 153041000 | EL5: 143906000 | EM5: 76047000 | EN5: 29663000 | FJ5: 8432000 | FK5: 2090000 | FO5: 22842000 | FP5: 21920000 | FT5: 16961000 | FU5: 5543000 | FV5: 202000 | FW5: 364000 | GD5: -13130000 | GE5: -2513000 | GF5: -3062000 | GG5: -2095000
A6: 5 | B6: АК БАНК, АО | C6: 1026300005170 | D6: 31 | E6: Денежное посредничество прочее
A7: 6 | B7: АЛЬЯНССЕТЬСТРОЙ, АО | C7: 1115904009880 | D7: 14 | E7: Строительство коммунальных объектов для обеспечения электроэнергией и телекоммуникациями | H7: 2938453 | I7: 3277318 | K7: 2746725 | L7: 2685779 | M7: 4360900 | P7: 77566000 | Q7: 67792000 | R7: 60290000 | S7: 57862000 | T7: 289000 | AJ7: 99174000 | AK7: 89795000 | AL7: 82270000 | AM7: 79819000 | AN7: 22244000 | AO7: 212209000 | AP7: 226034000 | AQ7: 226034000 | AR7: 223949000 | AS7: 223949000 | AT7: 91702000 | AU7: 89118000 | AV7: 107194000 | AW7: 72035000 | AX7: 13317000 | BF7: 286000 | BG7: 23093000 | BH7: 27251000 | BI7: 2105000 | BJ7: 1476000 | BK7: 1476000 | BL7: 1476000 | BM7: 1476000 | BN7: 307197000 | BO7: 317899000 | BP7: 336261000 | BQ7: 321824000 | BR7: 267264000 | BS7: 406371000 | BT7: 407694000 | BU7: 418531000 | BV7: 401643000 | BW7: 289508000 | BX7: 10000000 | BY7: 10000000 | BZ7: 10000000 | CA7: 10000000 | CB7: 10000000 | CH7: -64752000 | CI7: -86226000 | CJ7: -64035000 | CK7: -77096000 | CL7: -129701000 | CM7: -54252000 | CN7: -75726000 | CO7: -53535000 | CP7: -66596000 | CQ7: -119201000 | CW7: 1123000 | CX7: 1123000 | DB7: 3673000 | DC7: 3686000 | DD7: 2563000 | DE7: 2563000 | DF7: 2563000 | DG7: 12359000 | DH7: 12353000 | DI7: 12353000 | DJ7: 12353000 | DK7: 12353000 | DL7: 444591000 | DM7: 467381000 | DN7: 457150000 | DO7: 453323000 | DP7: 393793000 | EA7: 456950000 | EB7: 479734000 | EC7: 469503000 | ED7: 465676000 | EE7: 406146000 | EF7: 71835000 | EG7: 1145000 | EK7: 85733000 | EU7: 51679000 | EV7: 23897000 | EW7: 10117000 | EX7: 6140000 | EY7: 4098000 | FE7: 378000 | FJ7: 897000 | FO7: 22490000 | FP7: 7031000 | FQ7: 44789000 | FR7: 3000000 | FS7: 9268000 | FT7: 57894000 | FU7: 3927000 | FV7: 6840000 | FW7: 9921000 | FX7: 57775000 | FY7: 20176000 | GA7: -5642000 | GD7: -84328000 | GE7: -19648000 | GF7: 22190000 | GG7: -13061000 | GH7: -52605000
A8: 7 | B8: АНТЕЙ, ООО | C8: 1085916000477 | D8: 17 | E8: Управление эксплуатацией жилого фонда за вознаграждение или на договорной основе | P8: 1496000 | Q8: 7205000 | R8: 6909000 | AJ8: 1496000 | AK8: 7205000 | AL8: 6909000 | AO8: 2205000 | AP8: 608000 | AQ8: 500000 | AR8: 233000 | AS8: 233000 | AT8: 38472000 | AU8: 14456000 | AV8: 7610000 | AW8: 17806000 | AX8: 14298000 | BD8: 17451000 | BE8: 12106000 | BF8: 1009000 | BG8: 307000 | BH8: 1062000 | BN8: 58128000 | BO8: 27170000 | BP8: 9119000 | BQ8: 18346000 | BR8: 15593000 | BS8: 59624000 | BT8: 34375000 | BU8: 16028000 | BV8: 18346000 | BW8: 15593000 | BX8: 15000 | BY8: 15000 | BZ8: 15000 | CA8: 15000 | CB8: 15000 | CH8: 25831000 | CI8: -2719000 | CJ8: -9356000 | CK8: 6816000 | CL8: -722000 | CM8: 25846000 | CN8: -2704000 | CO8: -9341000 | CP8: 6831000 | CQ8: -707000 | CW8: 20550000 | DB8: 20550000 | DL8: 13228000 | DM8: 25791000 | DN8: 24330000 | DO8: 11515000 | DP8: 16300000 | DW8: 11288000 | DX8: 1039000 | EA8: 13228000 | EB8: 37079000 | EC8: 25369000 | ED8: 11515000 | EE8: 16300000 | EF8: 111609000 | EG8: 32742000 | EH8: 7778000 | EI8: 3700000 | EK8: 94923000 | EL8: 28040000 | EM8: 15221000 | EN8: 11887000 | EO8: 688000 | FO8: 168000 | FP8: 1626000 | FQ8: 2486000 | FR8: 19356000 | FS8: 11000 | FT8: 596000 | FU8: 26201000 | FV8: 545000 | FW8: 8256000 | FX8: 6749000 | FY8: -1413000 | FZ8: -1087000 | GA8: -123000 | GB8: -123000 | GC8: -113000 | GD8: 14845000 | GE8: -20960000 | GF8: -5625000 | GG8: 2790000 | GH8: -7539000
A9: 8 | B9: АРАЛТАУ-ЗЛАТО, ООО | C9: 1105902004064 | D9: 15 | E9: Добыча руд и песков драгоценных металлов и руд редких металлов | F9: 1486860 | G9: 476 | J9: 167992 | AU9: 50000 | AV9: 3000 | AW9: 199000 | AX9: 232000 | BD9: 1535000 | BE9: 784000 | BF9: 414000 | BG9: 1306000 | BN9: 1535000 | BO9: 834000 | BP9: 417000 | BQ9: 1505000 | BR9: 232000 | BS9: 1535000 | BT9: 834000 | BU9: 417000 | BV9: 1505000 | BW9: 232000 | BX9: 1018000 | BY9: 1018000 | BZ9: 1018000 | CA9: 1018000 | CB9: 1018000 | CH9: -386000 | CI9: -1094000 | CJ9: -1523000 | CK9: -6651000 | CL9: -7054000 | CM9: 632000 | CN9: -76000 | CO9: -505000 | CP9: -5633000 | CQ9: -6036000 | DL9: 903000 | DM9: 910000 | DN9: 922000 | DO9: 7138000 | DP9: 6268000 | EA9: 903000 | EB9: 910000 | EC9: 922000 | ED9: 7138000 | EE9: 6268000 | EU9: 306000 | EV9: 315000 | EW9: 42000 | EX9: 73000 | EY9: 182000 | FM9: 6641000 | FO9: 3720000 | FR9: 3229000 | FS9: 196000 | FT9: 460000 | FU9: 393000 | FV9: 383000 | FW9: 1447000 | FX9: 402000 | FY9: -465000 | GB9: -168000 | GD9: 2475000 | GE9: -708000 | GF9: -429000 | GG9: -5128000 | GH9: -403000
A10: 9 | B10: АРСИЭНТЕК, ООО | C10: 1137746779213 | D10: 12 | E10: Деятельность по предоставлению услуг телефонной связи | K10: 1603164 | L10: 1246348 | M10: 918660
A11: 10 | B11: АРТ-ПЕРМЬ, ООО | C11: 1165958121340 | D11: 8 | E11: Деятельность зрелищно-развлекательная прочая, не включенная в другие группировки | AX11: 10000000 | BR11: 10000000 | BW11: 10000000 | CQ11: 10000000
A12: 11 | B12: АТК, ООО | C12: 1125904005974 | D12: 13 | E12: Аренда и лизинг сельскохозяйственных машин и оборудования | P12: 9324000 | R12: 9324000 | S12: 51025000 | T12: 51024000 | AJ12: 9324000 | AL12: 9324000 | AM12: 51025000 | AN12: 51024000 | AO12: 632000 | AQ12: 632000 | AR12: 632000 | AT12: 42683000 | AV12: 42683000 | AW12: 42683000 | AX12: 42683000 | BD12: 17000 | BF12: 17000 | BG12: 3530000 | BH12: 1017000 | BI12: 100000 | BK12: 100000 | BL12: 100000 | BM12: 100000 | BN12: 43432000 | BP12: 43432000 | BQ12: 46945000 | BR12: 43800000 | BS12: 52756000 | BU12: 52756000 | BV12: 97970000 | BW12: 94824000 | BX12: 10000 | BZ12: 10000 | CA12: 10000 | CB12: 10000 | CH12: -21513000 | CJ12: -21513000 | CK12: -223653000 | CL12: -226798000 | CM12: -21503000 | CO12: -21503000 | CP12: -176942000 | CQ12: -180087000 | CU12: 274794000 | CV12: 274793000 | DE12: 274912000 | DF12: 274911000 | DG12: 68751000 | DI12: 68751000 | DL12: 5508000 | DN12: 5508000 | EA12: 74259000 | EC12: 74259000 | EK12: 16000 | EU12: 1770000 | FT12: 7000 | GD12: -1793000
A13: 12 | B13: АШАТЛИ-МОЛОКО, ООО | C13: 1115951000076 | D13: 14 | E13: Производство молочной продукции | F13: 180000 | H13: 418 | K13: 1318023 | L13: 3140000 | N13: 8772 | O13: 324840 | P13: 5370000 | Q13: 5211000 | R13: 5211000 | U13: 1000 | AJ13: 5630000 | AK13: 5211000 | AL13: 5211000 | AO13: 117299000 | AP13: 9222000 | AQ13: 9222000 | AT13: 221006000 | AU13: 9993000 | AV13: 9993000 | AW13: 558775000 | AX13: 558552000 | BD13: 5000 | BG13: 64000 | BI13: 1723000 | BN13: 342206000 | BO13: 19811000 | BP13: 19811000 | BQ13: 558839000 | BR13: 558552000 | BS13: 347836000 | BT13: 25022000 | BU13: 25022000 | BV13: 558839000 | BW13: 558552000 | BX13: 10000 | BY13: 10000 | BZ13: 10000 | CA13: 10000 | CH13: 48872000 | CI13: 11310000 | CJ13: 11310000 | CK13: 21353000 | CM13: 48882000 | CN13: 11320000 | CO13: 11320000 | CP13: 21363000 | CQ13: -254641000 | DB13: 106000 | DG13: 312000 | DL13: 298536000 | DM13: 13702000 | DN13: 13702000 | DO13: 537476000 | DP13: 813193000 | EA13: 298848000 | EB13: 13702000 | EC13: 13702000 | ED13: 537476000 | EE13: 813193000 | EF13: 410640000 | EG13: 373997000 | EK13: 373837000 | EL13: 401691000 | EP13: 416000 | EQ13: 410000 | EU13: 27391000 | EV13: 1608000 | FO13: 182000 | FP13: 72000 | FT13: 2164000 | FU13: 7922000 | FX13: 335000 | FY13: -106000 | GD13: 6908000 | GE13: -37562000 | GH13: -335000
A14: 13 | B14: БИОНИКА, ООО | C14: 1065902055020 | D14: 19 | E14: Деятельность ресторанов и кафе с полным ресторанным обслуживанием, кафетериев, ресторанов быстрого питания и самообслуживания | BD14: 1000 | BN14: 1000 | BS14: 1000 | BX14: 10000 | CH14: -803000 | CM14: -793000 | DL14: 794000 | EA14: 794000
A15: 14 | B15: БСК, ООО | C15: 1025901712352 | D15: 23 | E15: Производство прочих отделочных и завершающих работ | F15: 71334 | G15: 235352 | K15: 1612770 | L15: 1883051 | N15: 80621 | P15: 194000 | AJ15: 194000 | AO15: 123000 | AP15: 46000 | AT15: 10358000 | AU15: 845000 | AV15: 2699000 | AW15: 1754000 | AX15: 2815000 | BD15: 169000 | BE15: 20000 | BF15: 1161000 | BG15: 159000 | BH15: 776000 | BN15: 10650000 | BO15: 911000 | BP15: 3860000 | BQ15: 1913000 | BR15: 3591000 | BS15: 10844000 | BT15: 911000 | BU15: 3860000 | BV15: 1913000 | BW15: 3591000 | CM15: 3811000 | CN15: 610000 | CO15: -3000000 | CP15: -8973000 | CQ15: -3528000 | DL15: 7033000 | DM15: 301000 | DN15: 6860000 | DO15: 10886000 | DP15: 7119000 | EA15: 7033000 | EB15: 301000 | EC15: 6860000 | ED15: 10886000 | EE15: 7119000 | EF15: 13019000 | EG15: 8442000 | EH15: 2278000 | EI15: 419000 | EK15: 11699000 | EL15: 8123000 | EM15: 2121000 | EN15: 652000 | EO15: 523000 | FO15: 94000 | FS15: 6203000 | FT15: 214000 | FU15: 3493000 | FV15: 3767000 | FW15: 5740000 | FX15: 5680000 | FY15: 240000 | FZ15: 47000 | GD15: 960000 | GE15: -3221000 | GF15: -3610000 | GG15: -5973000
A16: 15 | B16: БСП, ООО | C16: 1085907002697 | D16: 16 | E16: Предоставление услуг по бурению, связанному с добычей нефти, газа и газового конденсата | O16: 943343 | S16: 10892000 | T16: 1035000 | AM16: 10892000 | AN16: 1035000 | AW16: 888701000 | AX16: 9500000 | BH16: 7195000 | BQ16: 888701000 | BR16: 16695000 | BV16: 899593000 | BW16: 17730000 | CP16: 624167000 | CQ16: -318466000 | DO16: 275426000 | DP16: 335830000 | DZ16: 366000 | ED16: 275426000 | EE16: 336196000 | EI16: 12856000 | EJ16: 2197000 | EN16: 15128000 | EO16: 16468000 | FS16: 10015000 | FW16: 2479000 | FX16: 938377000 | GG16: -4751000 | GH16: -942633000
A17: 16 | B17: БУЭСМ, ООО | C17: 1026600834479 | D17: 22 | E17: Строительство жилых и нежилых зданий | F17: 4703 | G17: 92273 | K17: 3521622 | L17: 97020 | N17: 31099 | O17: 45774 | P17: 152000 | Q17: 201000 | AJ17: 152000 | AK17: 201000 | AO17: 17768000 | AP17: 86870000 | AT17: 16542000 | AU17: 20531000 | BD17: 12879000 | BI17: 2503000 | BJ17: 3972000 | BN17: 49692000 | BO17: 111712000 | BS17: 49844000 | BT17: 111914000 | BX17: 10000 | BY17: 10000 | CH17: 1993000 | CI17: 2586000 | CM17: 2003000 | CN17: 2596000 | DG17: 2700000 | DH17: 16199000 | DL17: 45141000 | DM17: 93118000 | EA17: 47841000 | EB17: 109317000 | EF17: 5397000 | EG17: 31348000 | EK17: 5536000 | EL17: 29384000 | EU17: 3018000 | FJ17: 1000 | FK17: 1399000 | FO17: 8643000 | FT17: 5051000 | FU17: 918000 | FY17: -89000 | FZ17: 16000 | GD17: 345000 | GE17: -759000
A18: 17 | B18: ВЕЛИКОЛЕНСКОЕ, ООО | C18: 1025901892455 | D18: 30 | E18: Животноводство | K18: 1053761 | M18: 1695299 | P18: 104525000 | Q18: 77248000 | R18: 67425000 | S18: 67813000 | T18: 60278000 | Z18: 60000 | AA18: 60000 | AB18: 60000 | AC18: 60000 | AD18: 60000 | AE18: 4076000 | AF18: 4076000 | AG18: 3869000 | AH18: 3869000 | AI18: 3869000 | AJ18: 108661000 | AK18: 81384000 | AL18: 71354000 | AM18: 71742000 | AN18: 64207000 | AO18: 116271000 | AP18: 77831000 | AQ18: 64182000 | AR18: 50545000 | AS18: 32418000 | AT18: 5849000 | AU18: 6299000 | AV18: 9547000 | AW18: 7711000 | AX18: 7820000 | BD18: 10000 | BE18: 2980000 | BF18: 135000 | BG18: 163000 | BH18: 66000 | BI18: 957000 | BJ18: 1387000 | BK18: 957000 | BL18: 957000 | BM18: 957000 | BN18: 123087000 | BO18: 88497000 | BP18: 74821000 | BQ18: 59376000 | BR18: 41261000 | BS18: 231748000 | BT18: 169881000 | BU18: 146175000 | BV18: 131118000 | BW18: 105468000 | BX18: 10000 | BY18: 10000 | BZ18: 10000 | CA18: 10000 | CB18: 10000 | CC18: 5522000 | CD18: 5522000 | CE18: 5522000 | CF18: 5522000 | CG18: 5522000 | CH18: 84551000 | CI18: 32797000 | CJ18: 10823000 | CK18: -8903000 | CL18: -54390000 | CM18: 138217000 | CN18: 86463000 | CO18: 64489000 | CP18: 44763000 | CQ18: -724000 | DG18: 2048000 | DH18: 2075000 | DI18: 2075000 | DJ18: 2075000 | DK18: 2075000 | DL18: 91483000 | DM18: 81343000 | DN18: 79611000 | DO18: 84280000 | DP18: 104117000 | EA18: 93531000 | EB18: 83418000 | EC18: 81686000 | ED18: 86355000 | EE18: 106192000 | EF18: 79364000 | EG18: 57568000 | EH18: 48791000 | EI18: 60449000 | EJ18: 53594000 | EK18: 134823000 | EL18: 105382000 | EM18: 76646000 | EN18: 72171000 | EO18: 91580000 | FJ18: 95000 | FK18: 27000 | FO18: 12010000 | FP18: 26833000 | FQ18: 22473000 | FR18: 3167000 | FS18: 4420000 | FT18: 11227000 | FU18: 30746000 | FV18: 15893000 | FW18: 11171000 | FX18: 11921000 | GD18: -54771000 | GE18: -51754000 | GF18: -21275000 | GG18: -19726000 | GH18: -45487000
A19: 18 | B19: ВЕМСЕЙ, ООО | C19: 1157847079940 | D19: 10 | E19: Торговля розничная одеждой в специализированных магазинах | F19: 137359 | G19: 109900 | H19: 41221 | I19: 549539 | J19: 30863 | K19: 24443877 | L19: 43222813 | M19: 37342870 | N19: 18968706 | O19: 6590111 | P19: 496000 | Q19: 432000 | AJ19: 652000 | AK19: 2923000 | AL19: 3953000 | AM19: 2938000 | AN19: 3064000 | AO19: 634520000 | AP19: 443883000 | AQ19: 71992000 | AR19: 37221000 | AS19: 29783000 | AT19: 65258000 | AU19: 209011000 | AV19: 263000000 | AW19: 257268000 | AX19: 193444000 | AY19: 2983000 | AZ19: 6130000 | BA19: 8762000 | BB19: 8661000 | BC19: 8802000 | BD19: 9170000 | BE19: 2858000 | BF19: 3558000 | BG19: 5195000 | BH19: 458000 | BI19: 39000 | BJ19: 14000 | BM19: 1045000 | BN19: 711970000 | BO19: 661896000 | BP19: 347312000 | BQ19: 308345000 | BR19: 233532000 | BS19: 712622000 | BT19: 664819000 | BU19: 351265000 | BV19: 311282000 | BW19: 236595000 | BX19: 30000 | BY19: 30000 | BZ19: 30000 | CA19: 30000 | CB19: 30000 | CH19: 40071000 | CI19: 35145000 | CJ19: 1113000 | CK19: 2763000 | CL19: 3496000 | CM19: 40101000 | CN19: 35175000 | CO19: 1143000 | CP19: 2793000 | CQ19: 3526000 | DB19: 21000 | DC19: 142000 | DF19: 15000 | DG19: 5074000 | DH19: 3427000 | DI19: 7410000 | DJ19: 33587000 | DK19: 5864000 | DL19: 667219000 | DM19: 625868000 | DN19: 342506000 | DO19: 274902000 | DP19: 227191000 | DQ19: 207000 | DR19: 207000 | DS19: 207000 | EA19: 672500000 | EB19: 629502000 | EC19: 350123000 | ED19: 308489000 | EE19: 233055000 | EF19: 314616000 | EG19: 370254000 | EH19: 185892000 | EI19: 46513000 | EJ19: 26263000 | EK19: 205525000 | EL19: 322434000 | EM19: 160555000 | EN19: 43639000 | EO19: 10704000 | EP19: 136706000 | EQ19: 154549000 | ER19: 84362000 | ES19: 38783000 | ET19: 24548000 | FJ19: 105000 | FK19: 41000 | FO19: 45294000 | FP19: 114977000 | FQ19: 273160000 | FR19: 61753000 | FS19: 23463000 | FT19: 17324000 | FU19: 14308000 | FV19: 244919000 | FW19: 21498000 | FX19: 13666000 | FY19: -29000 | FZ19: 2214000 | GA19: 1707000 | GB19: -1191000 | GC19: -91000 | GD19: -250000 | GE19: -4925000 | GF19: -33136000 | GG19: 2172000 | GH19: 731000
A20: 19 | B20: ВЕСТКРАУНД, ООО | C20: 1155958076218 | D20: 10 | E20: Строительство автомобильных дорог и автомагистралей | G20: 425990 | L20: 999989 | M20: 13694 | P20: 3482000 | Q20: 2370000 | Z20: 19000 | AA20: 19000 | AJ20: 3501000 | AK20: 2389000 | AO20: 30835000 | AT20: 44545000 | AU20: 28830000 | AW20: 87109000 | AX20: 87109000 | BD20: 49000 | BE20: 1393000 | BG20: 71000 | BN20: 75429000 | BO20: 30223000 | BQ20: 87180000 | BR20: 87109000 | BS20: 78929000 | BT20: 32611000 | BV20: 87180000 | BW20: 87109000 | CM20: 7969000 | CN20: -18724000 | CP20: -132191000 | CQ20: -132262000 | CW20: 411000 | CX20: 411000 | DB20: 411000 | DC20: 411000 | DG20: 7666000 | DH20: 12737000 | DL20: 62883000 | DM20: 38187000 | DO20: 219371000 | DP20: 219371000 | EA20: 70549000 | EB20: 50924000 | ED20: 219371000 | EE20: 219371000 | EF20: 179332000 | EG20: 35387000 | EK20: 156342000 | EL20: 80269000 | FJ20: 13604000 | FK20: 1684000 | FO20: 2785000 | FP20: 56949000 | FT20: 2754000 | FU20: 36917000 | FW20: 203000 | FY20: 7032000 | FZ20: 158000 | GD20: 2385000 | GE20: -26692000 | GG20: -203000
A21: 20 | B21: ВИБКОМ, ООО | C21: 1065904113197 | D21: 19 | E21: Деятельность ресторанов и услуги по доставке продуктов питания | Q21: 9121000 | R21: 8401000 | AK21: 9121000 | AL21: 8401000 | AO21: 1949000 | AP21: 1854000 | AQ21: 2006000 | AU21: 1051000 | AV21: 126000 | BD21: 115000 | BE21: 57000 | BF21: 15000 | BI21: 9852000 | BJ21: 1278000 | BK21: 3852000 | BN21: 11916000 | BO21: 4240000 | BP21: 5999000 | BS21: 11916000 | BT21: 13361000 | BU21: 14400000 | BX21: 10000 | BY21: 10000 | BZ21: 10000 | CH21: 10138000 | CI21: 11314000 | CJ21: 11388000 | CM21: 10148000 | CN21: 11324000 | CO21: 11398000 | CQ21: -3715000 | DG21: 1000000 | DH21: 1911000 | DI21: 3002000 | DL21: 768000 | DM21: 126000 | DP21: 3715000 | EA21: 1768000 | EB21: 2037000 | EC21: 3002000 | EE21: 3715000 | EF21: 7229000 | EG21: 10884000 | EH21: 7652000 | EK21: 8630000 | EL21: 10599000 | EM21: 7327000 | FL21: 9000 | FO21: 428000 | FP21: 1103000 | FQ21: 288000 | FT21: 64000 | FU21: 95000 | FV21: 452000 | FX21: 96000 | FY21: -72000 | FZ21: -117000 | GA21: -78000 | GD21: -1109000 | GE21: 1176000 | GF21: 74000 | GH21: -96000
A22: 21 | B22: ВЛБАНК (АО) | C22: 1063800023572 | D22: 19 | E22: Денежное посредничество прочее
A23: 22 | B23: ВНЕШПРОМБАНК, ООО | C23: 1027700514049 | D23: 30 | E23: Денежное посредничество прочее
A24: 23 | B24: ВОЛГА, ООО | C24: 5177746098844 | D24: 8 | E24: Торговля розничная большим товарным ассортиментом с преобладанием непродовольственных товаров в неспециализированных магазинах | F24: 222000 | G24: 23305756 | K24: 2031396 | L24: 11507825 | M24: 2027 | N24: 37 | P24: 1291000 | Q24: 111000 | AE24: 17000 | AF24: 1197000 | AJ24: 3870000 | AK24: 115273000 | AM24: 1100000 | AO24: 664425000 | AP24: 423415000 | AR24: 5000 | AS24: 5000 | AT24: 1922091000 | AU24: 1621127000 | AW24: 24000 | AY24: 2240000 | AZ24: 2486000 | BD24: 366000 | BE24: 5550000 | BG24: 101000 | BH24: 107000 | BJ24: 28602000 | BN24: 2625770000 | BO24: 2086572000 | BQ24: 130000 | BR24: 112000 | BS24: 2629640000 | BT24: 2201844000 | BV24: 1230000 | BW24: 112000 | BX24: 20000 | BY24: 20000 | CA24: 20000 | CB24: 20000 | CH24: 37932000 | CI24: -226930000 | CK24: -2826678000 | CL24: -2836238000 | CM24: 37952000 | CN24: -226910000 | CP24: -2826658000 | CQ24: -2836218000 | DB24: 137000 | DC24: 22000 | DG24: 439829000 | DH24: 489646000 | DL24: 2147151000 | DM24: 1928670000 | DO24: 2827888000 | DP24: 2836330000 | EA24: 2591552000 | EB24: 2428732000 | ED24: 2827888000 | EE24: 2836330000 | EF24: 1805986000 | EG24: 640098000 | EI24: 92000 | EJ24: 149000 | EK24: 1356738000 | EL24: 503785000 | EN24: 1420000 | EO24: 8518000 | EP24: 407832000 | EQ24: 281605000 | FE24: 190000 | FF24: 246000 | FJ24: 24683000 | FK24: 49817000 | FO24: 204103000 | FP24: 40770000 | FR24: 2000000 | FT24: 175431000 | FU24: 139440000 | FW24: 901000 | FX24: 1191000 | FY24: -9583000 | FZ24: 52606000 | GD24: 36012000 | GE24: -235060000 | GG24: -229000 | GH24: -9560000
A25: 24 | B25: ВОСТОК, ООО СК | C25: 1115904009154 | D25: 14 | E25: Консультирование по вопросам коммерческой деятельности и управления | G25: 2092 | H25: 95094 | K25: 10920016 | P25: 769000 | Q25: 769000 | R25: 769000 | AJ25: 808000 | AK25: 808000 | AL25: 808000 | AT25: 21377000 | AU25: 21377000 | AV25: 1489000 | AW25: 1489000 | AX25: 1489000 | BI25: 27000 | BJ25: 27000 | BK25: 27000 | BN25: 21404000 | BO25: 21404000 | BP25: 1516000 | BQ25: 1489000 | BR25: 1489000 | BS25: 22212000 | BT25: 22212000 | BU25: 2324000 | BV25: 1489000 | BW25: 1489000 | BX25: 10000 | BY25: 10000 | BZ25: 10000 | CA25: 10000 | CB25: 10000 | CH25: -30424000 | CI25: -30424000 | CJ25: -42835000 | CK25: -42835000 | CL25: -42835000 | CM25: -30414000 | CN25: -30414000 | CO25: -42825000 | CP25: -42825000 | CQ25: -42825000 | CW25: 104000 | CX25: 104000 | CY25: 104000 | DB25: 104000 | DC25: 104000 | DD25: 104000 | DG25: 346000 | DH25: 346000 | DL25: 52029000 | DM25: 52029000 | DN25: 44898000 | DO25: 44314000 | DP25: 44314000 | EA25: 52522000 | EB25: 52522000 | EC25: 45045000 | ED25: 44314000 | EE25: 44314000 | EF25: 86481000 | EK25: 93453000 | EU25: 12684000 | FO25: 7971000 | FT25: 47483000 | GD25: -59240000
A26: 25 | B26: ГАЗПРОМ СПЕЦГАЗАВТОТРАНС, ПАО | C26: 1021801586047 | D26: 32 | E26: Строительство инженерных коммуникаций для водоснабжения и водоотведения, газоснабжения | O26: 546090 | P26: 367420000 | Q26: 353701000 | R26: 298856000 | S26: 224123000 | T26: 112842000 | Z26: 6125000 | AA26: 8858000 | AB26: 4736000 | AC26: 4673000 | AD26: 4119000 | AE26: 3000 | AJ26: 885015000 | AK26: 891352000 | AL26: 816537000 | AM26: 675994000 | AN26: 516609000 | AO26: 439645000 | AP26: 445688000 | AQ26: 443054000 | AR26: 435788000 | AS26: 412956000 | AT26: 1228777000 | AU26: 1265599000 | AV26: 1362357000 | AW26: 1798613000 | AX26: 1660245000 | BD26: 55117000 | BE26: 283000 | BF26: 9733000 | BG26: 4162000 | BH26: 2579000 | BI26: 4979000 | BJ26: 4980000 | BK26: 4980000 | BL26: 4980000 | BM26: 4979000 | BN26: 1730283000 | BO26: 1718310000 | BP26: 1821877000 | BQ26: 2245295000 | BR26: 2080776000 | BS26: 2615298000 | BT26: 2609662000 | BU26: 2638414000 | BV26: 2921289000 | BW26: 2597385000 | BX26: 977000 | BY26: 977000 | BZ26: 977000 | CA26: 977000 | CB26: 977000 | CC26: 425740000 | CD26: 417614000 | CE26: 326775000 | CF26: 286040000 | CG26: 163399000 | CH26: -2445078000 | CI26: -2508018000 | CJ26: -2800056000 | CK26: -2344725000 | CL26: -2000784000 | CM26: -1472257000 | CN26: -1543323000 | CO26: -1926200000 | CP26: -1511604000 | CQ26: -1290304000 | DB26: 36318000 | DC26: 36604000 | DD26: 28904000 | DE26: 23238000 | DF26: 16353000 | DG26: 297268000 | DH26: 307908000 | DI26: 318548000 | DJ26: 329188000 | DK26: 270624000 | DL26: 3734172000 | DM26: 3791148000 | DN26: 4201778000 | DO26: 4064303000 | DP26: 3585076000 | EA26: 4051237000 | EB26: 4116381000 | EC26: 4535710000 | ED26: 4409655000 | EE26: 3871336000 | EF26: 319294000 | EG26: 119395000 | EH26: 171801000 | EI26: 30107000 | EJ26: 6124000 | EK26: 421764000 | EL26: 158353000 | EM26: 95185000 | EN26: 75580000 | EU26: 81594000 | EV26: 66180000 | EW26: 69427000 | EX26: 51367000 | EY26: 121350000 | EZ26: 279000 | FA26: 230000 | FB26: 934000 | FJ26: 10640000 | FK26: 10640000 | FL26: 10640000 | FM26: 10640000 | FO26: 50773000 | FP26: 39541000 | FQ26: 322160000 | FR26: 908756000 | FS26: 583635000 | FT26: 26081000 | FU26: 12102000 | FV26: 220469000 | FW26: 260369000 | FX26: 139882000 | FY26: 34254000 | FZ26: 17044000 | GA26: -20071000 | GB26: -126297000 | GC26: -78886000 | GD26: -307791000 | GE26: -71066000 | GF26: -382876000 | GG26: 414586000 | GH26: 226364000
A27: 26 | B27: ГЕОСТРОЙ, ООО | C27: 1037739931008 | D27: 21 | E27: Создание геодезической, нивелирной, гравиметрической сетей | F27: 544 | G27: 258985 | H27: 181 | K27: 1659456 | L27: 17058842 | M27: 1101006 | Q27: 31840000 | R27: 4113000 | S27: 2211000 | AK27: 31840000 | AL27: 4113000 | AM27: 2211000 | AU27: 420000 | AV27: 33866000 | AW27: 6164000 | AX27: 79710000 | BE27: 81000 | BF27: 4143000 | BG27: 5384000 | BH27: 6028000 | BO27: 501000 | BP27: 38009000 | BQ27: 11548000 | BR27: 85738000 | BT27: 32341000 | BU27: 42121000 | BV27: 13758000 | BW27: 85738000 | BY27: 10000 | BZ27: 10000 | CA27: 10000 | CB27: 10000 | CI27: -57662000 | CJ27: -47274000 | CK27: -54707000 | CL27: 13300000 | CN27: -57652000 | CO27: -47264000 | CP27: -54697000 | CQ27: 13310000 | DM27: 89993000 | DN27: 89385000 | DO27: 68455000 | DP27: 72428000 | EB27: 89993000 | EC27: 89385000 | ED27: 68455000 | EE27: 72428000
A28: 27 | B28: ГИДРОТЕПЛОСТРОЙ, ООО | C28: 1165958100703 | D28: 9 | E28: Строительство жилых и нежилых зданий | I28: 273659 | J28: 27220 | K28: 5852 | L28: 6113 | N28: 536 | O28: 72578 | P28: 3628000 | Q28: 2267000 | R28: 907000 | AJ28: 3670000 | AK28: 2303000 | AL28: 937000 | AO28: 2342000 | AP28: 5000 | AT28: 2535000 | AU28: 3869000 | AV28: 3142000 | BI28: 128000 | BN28: 5303000 | BO28: 3937000 | BP28: 3205000 | BS28: 8973000 | BT28: 6240000 | BU28: 4142000 | BX28: 10000 | BY28: 10000 | BZ28: 10000 | CH28: -3837000 | CI28: -5321000 | CJ28: -7417000 | CM28: -3827000 | CN28: -5311000 | CO28: -7407000 | CP28: -7671000 | CR28: 1747000 | CS28: 2312000 | CT28: 2312000 | DB28: 1747000 | DC28: 2312000 | DD28: 2312000 | DL28: 11053000 | DM28: 9239000 | DN28: 9237000 | DO28: 7671000 | EA28: 11053000 | EB28: 9239000 | EC28: 9237000 | ED28: 7671000 | EF28: 1461000 | EG28: 2327000 | EK28: 1119000 | EL28: 2336000 | EM28: 1730000 | EP28: 2000 | EU28: 2372000 | EV28: 1470000 | FO28: 2549000 | FT28: 922000 | FV28: 366000 | FW28: 264000 | FY28: -18000 | FZ28: -5000 | GD28: -423000 | GE28: -1484000 | GF28: -2096000 | GG28: -264000
A29: 28 | B29: ГЛАСИС ПЕРМЬ, ООО | C29: 1085902009313 | D29: 17 | E29: Торговля автомобильными деталями, узлами и принадлежностями | P29: 1098000 | Q29: 751000 | R29: 73000 | AJ29: 1098000 | AK29: 751000 | AL29: 73000 | AQ29: 150000 | AT29: 6911000 | AU29: 11908000 | AV29: 13847000 | BD29: 138000 | BE29: 498000 | BF29: 365000 | BN29: 7049000 | BO29: 12406000 | BP29: 14362000 | BS29: 8147000 | BT29: 13157000 | BU29: 14435000 | CM29: 1795000 | CN29: 3503000 | CO29: 5482000 | CR29: 98000 | CS29: 1500000 | CT29: 3349000 | DB29: 98000 | DC29: 1500000 | DD29: 3349000 | DH29: 5061000 | DI29: 2889000 | DL29: 6254000 | DM29: 3093000 | DN29: 2715000 | EA29: 6254000 | EB29: 8154000 | EC29: 5604000 | EF29: 8464000 | EG29: 13152000 | EH29: 7768000 | EK29: 7205000 | EL29: 9149000 | EM29: 5604000 | FK29: 285000 | FL29: 175000 | FO29: 3044000 | FP29: 255000 | FQ29: 150000 | FT29: 2238000 | FU29: 1176000 | FV29: 675000 | FY29: 565000 | FZ29: 1089000 | GA29: 212000 | GD29: 1500000 | GE29: 1708000 | GF29: 1252000
A30: 29 | B30: ГОДОВАЛОВ, ООО | C30: 1065908029615 | D30: 18 | E30: Торговля оптовая фармацевтической продукцией | P30: 72041000 | Q30: 52973000 | R30: 89410000 | S30: 12870000 | T30: 12870000 | Z30: 878761000 | AA30: 899286000 | AB30: 920895000 | AC30: 67938000 | AD30: 71677000 | AJ30: 950802000 | AK30: 952259000 | AL30: 1010305000 | AM30: 80808000 | AN30: 84547000 | AO30: 6148227000 | AP30: 5999859000 | AQ30: 6028868000 | AR30: 15816000 | AS30: 15816000 | AT30: 2673379000 | AU30: 3233937000 | AV30: 5335774000 | AW30: 5062119000 | AX30: 5038140000 | BD30: 3402000 | BE30: 1892000 | BF30: 79059000 | BG30: 4015000 | BH30: 610000 | BL30: 187000 | BM30: 143000 | BN30: 8834501000 | BO30: 9272043000 | BP30: 11529586000 | BQ30: 5090073000 | BR30: 5062645000 | BS30: 9785303000 | BT30: 10224302000 | BU30: 12539891000 | BV30: 5170881000 | BW30: 5147192000 | BX30: 200000 | BY30: 200000 | BZ30: 200000 | CA30: 200000 | CB30: 200000 | CH30: 1230753000 | CI30: 1428233000 | CJ30: 1636796000 | CK30: -3501497000 | CL30: -3518048000 | CM30: 1230953000 | CN30: 1428433000 | CO30: 1636996000 | CP30: -3501297000 | CQ30: -3517848000 | CR30: 3302000 | CS30: 1849000 | CT30: 1870000 | CU30: 4086864000 | CV30: 4086684000 | DB30: 3302000 | DC30: 1849000 | DD30: 1870000 | DE30: 4086864000 | DF30: 4086684000 | DG30: 2774000000 | DH30: 3304063000 | DI30: 4452075000 | DL30: 5777048000 | DM30: 5489957000 | DN30: 6448950000 | DO30: 4585314000 | DP30: 4578356000 | EA30: 8551048000 | EB30: 8794020000 | EC30: 10901025000 | ED30: 4585314000 | EE30: 4578356000 | EF30: 20322825000 | EG30: 17415422000 | EH30: 17414894000 | EI30: 7384425000 | EJ30: 242000 | EK30: 19891083000 | EL30: 16919131000 | EM30: 16655535000 | EN30: 7323049000 | EP30: 889453000 | EQ30: 794697000 | ER30: 776373000 | ES30: 558244000 | ET30: 20864000 | FE30: 22173000 | FF30: 21191000 | FG30: 21936000 | FH30: 4791000 | FI30: 3739000 | FJ30: 237808000 | FK30: 277905000 | FL30: 539048000 | FM30: 269187000 | FO30: 1193766000 | FP30: 1166975000 | FQ30: 1028320000 | FR30: 507121000 | FS30: 1115000 | FT30: 268982000 | FU30: 360848000 | FV30: 245209000 | FW30: 729924000 | FX30: 781000 | FY30: -65844000 | FZ30: -53527000 | GA30: -49999000 | GD30: 185594000 | GE30: 197480000 | GF30: 198986000 | GG30: -5138293000 | GH30: -16549000
A31: 30 | B31: ГОРНОЗАВОДСК-ВОДОСНАБЖЕНИЕ, ООО | C31: 1195958008070 | D31: 6 | E31: Забор, очистка и распределение воды | F31: 72154 | K31: 2156725 | L31: 213320 | M31: 32994 | P31: 693000 | Q31: 296000 | AJ31: 1433000 | AK31: 296000 | AO31: 327000 | AP31: 362000 | AQ31: 122000 | AR31: 122000 | AS31: 12000 | AT31: 7914000 | AU31: 10762000 | AV31: 7437000 | AW31: 7919000 | AX31: 4165000 | BD31: 693000 | BE31: 315000 | BF31: 1649000 | BG31: 434000 | BH31: 48000 | BI31: 101000 | BJ31: 54000 | BN31: 9034000 | BO31: 11493000 | BP31: 9208000 | BQ31: 8475000 | BR31: 4225000 | BS31: 10467000 | BT31: 11789000 | BU31: 9208000 | BV31: 8475000 | BW31: 4225000 | BX31: 10000 | BY31: 10000 | BZ31: 10000 | CA31: 10000 | CB31: 10000 | CH31: -2958000 | CI31: -7802000 | CJ31: -8074000 | CK31: -10126000 | CL31: -14376000 | CM31: -2948000 | CN31: -7792000 | CO31: -8064000 | CP31: -10116000 | CQ31: -14366000 | CW31: 535000 | CX31: 258000 | DB31: 535000 | DC31: 258000 | DL31: 12467000 | DM31: 19187000 | DN31: 17272000 | DO31: 18591000 | DP31: 18591000 | DW31: 136000 | EA31: 12879000 | EB31: 19323000 | EC31: 17272000 | ED31: 18591000 | EE31: 18591000 | EF31: 41701000 | EG31: 21913000 | EH31: 6326000 | EK31: 43102000 | EL31: 26708000 | EM31: 6481000 | EV31: 438000 | EW31: 524000 | EX31: 533000 | FO31: 335000 | FP31: 369000 | FQ31: 482000 | FR31: 507000 | FS31: 2777000 | FT31: 137000 | FU31: 195000 | FV31: 75000 | FX31: 7027000 | FY31: -258000 | GD31: -962000 | GE31: -4844000 | GF31: -272000 | GG31: -26000 | GH31: -4250000
A32: 31 | B32: ГОРЫ, ООО | C32: 1055907103603 | D32: 19 | E32: Животноводство | H32: 82829 | J32: 29502 | K32: 1376647 | L32: 195199 | M32: 1072090 | N32: 196029 | P32: 42270000 | Q32: 36546000 | R32: 81670000 | S32: 39714000 | T32: 38376000 | Z32: 33000 | AJ32: 42303000 | AK32: 36546000 | AL32: 81670000 | AM32: 39714000 | AN32: 38376000 | AO32: 47024000 | AP32: 22054000 | AQ32: 940000 | AR32: 3624000 | AS32: 3624000 | AT32: 138488000 | AU32: 142099000 | AW32: 115116000 | AX32: 115116000 | AY32: 23130000 | AZ32: 23257000 | BD32: 4000 | BE32: 517000 | BF32: 841000 | BG32: 87000 | BI32: 15000 | BJ32: 32000 | BN32: 208887000 | BO32: 187960000 | BP32: 1781000 | BQ32: 118827000 | BR32: 118740000 | BS32: 251190000 | BT32: 224505000 | BU32: 83451000 | BV32: 158541000 | BW32: 157116000 | BX32: 18460000 | BY32: 18460000 | BZ32: 18460000 | CH32: 87764000 | CI32: 65475000 | CJ32: -251841000 | CM32: 106224000 | CN32: 83935000 | CO32: -233381000 | CP32: -158290000 | CQ32: -158172000 | CR32: 1000 | CS32: 1000 | DB32: 1000 | DC32: 1000 | DG32: 33765000 | DH32: 34274000 | DL32: 111199000 | DM32: 106295000 | DN32: 316749000 | DO32: 316749000 | DP32: 315206000 | DX32: 83000 | DY32: 82000 | DZ32: 82000 | EA32: 144964000 | EB32: 140569000 | EC32: 316832000 | ED32: 316831000 | EE32: 315288000 | EF32: 58846000 | EG32: 66305000 | EH32: 28485000 | EI32: 1200000 | EJ32: 1338000 | EK32: 62781000 | EL32: 79636000 | EM32: 20653000 | EV32: 4780000 | EW32: 9134000 | FJ32: 859000 | FK32: 1326000 | FO32: 7879000 | FP32: 8912000 | FQ32: 2014000 | FT32: 10132000 | FU32: 11753000 | FV32: 2316000 | FW32: 1844000 | FX32: 1190000 | GA32: -83000 | GC32: 30000 | GD32: -7047000 | GE32: -22278000 | GF32: -1687000 | GG32: -644000 | GH32: 118000
A33: 32 | B33: ГОСЗЕМКАДАСТРСЪЕМКА -ВИСХАГИ, АО | C33: 1127747072023 | D33: 31 | E33: Деятельность геодезическая и картографическая | I33: 3010667 | J33: 70053348 | N33: 34896060 | O33: 2141707 | P33: 486406000 | Q33: 452039000 | R33: 419622000 | S33: 10641000 | T33: 6033000 | AJ33: 558509000 | AK33: 524142000 | AL33: 419622000 | AM33: 10641000 | AN33: 6033000 | AO33: 45067000 | AP33: 1986000 | AQ33: 1857000 | AT33: 92211000 | AU33: 82000000 | AV33: 18678000 | AW33: 1157000 | AX33: 6088000 | BD33: 1843000 | BE33: 161000 | BG33: 152000 | BH33: 4071000 | BI33: 111132000 | BJ33: 116988000 | BL33: 313810000 | BM33: 26264000 | BN33: 250253000 | BO33: 201135000 | BP33: 20535000 | BQ33: 315119000 | BR33: 36423000 | BS33: 808762000 | BT33: 725277000 | BU33: 440157000 | BV33: 325760000 | BW33: 42456000 | BX33: 1214571000 | BY33: 1214571000 | BZ33: 1214571000 | CA33: 1214571000 | CB33: 1214571000 | CH33: -1819547000 | CI33: -1817304000 | CJ33: -1816019000 | CK33: -1752629000 | CL33: -1783438000 | CM33: -601939000 | CN33: -599696000 | CO33: -598411000 | CP33: -535021000 | CQ33: -565830000 | CR33: 171000 | CS33: 171000 | CT33: 273330000 | CU33: 309630000 | CV33: 277487000 | DB33: 288000 | DC33: 288000 | DD33: 273447000 | DE33: 309630000 | DF33: 277487000 | DG33: 273158000 | DH33: 273158000 | DL33: 1136958000 | DM33: 1051230000 | DN33: 763945000 | DO33: 547255000 | DP33: 326462000 | DQ33: 11000 | DR33: 11000 | EA33: 1410413000 | EB33: 1324685000 | EC33: 765121000 | ED33: 551151000 | EE33: 330799000 | EF33: 167000 | EG33: 28080000 | EH33: 16390000 | EI33: 15261000 | EJ33: 10909000 | EL33: 36527000 | EU33: 83644000 | EV33: 73851000 | EW33: 51431000 | EX33: 35416000 | EY33: 26182000 | FE33: 38000 | FO33: 57557000 | FP33: 105466000 | FQ33: 376846000 | FR33: 304201000 | FS33: 87249000 | FT33: 39796000 | FU33: 20364000 | FV33: 340241000 | FW33: 100130000 | FX33: 25609000 | FZ33: -561000 | GB33: -43612000 | GC33: -10742000 | GD33: -108176000 | GE33: 2243000 | GF33: 1285000 | GG33: 140304000 | GH33: 35625000
A34: 33 | B34: ГРУППА КОМПАНИЙ СВЯЗНОЙ, АО | C34: 1047796913735 | D34: 20 | E34: Деятельность агентов по оптовой торговле радио- и телеаппаратурой, техническими носителями информации | K34: 652000 | L34: 722855 | M34: 1334921 | N34: 165861 | O34: 397232 | Z34: 159856000 | AA34: 155855000 | AB34: 155855000 | AG34: 79000 | AH34: 71000 | AI34: 65000 | AJ34: 159883000 | AK34: 155861000 | AL34: 156517000 | AM34: 3535000 | AN34: 7059000 | AT34: 1030190000 | AU34: 2403716000 | AV34: 2536844000 | AW34: 1557753000 | AX34: 1557972000 | BD34: 11692000 | BE34: 2784000 | BF34: 44000 | BG34: 4000 | BH34: 334000 | BL34: 3000 | BN34: 1041882000 | BO34: 2406500000 | BP34: 2536888000 | BQ34: 1557760000 | BR34: 1558350000 | BS34: 1201765000 | BT34: 2562361000 | BU34: 2693405000 | BV34: 1561295000 | BW34: 1565409000 | BX34: 1105000000 | BY34: 1105000000 | BZ34: 1105000000 | CA34: 1105000000 | CB34: 1105000000 | CH34: -493911000 | CI34: -504832000 | CJ34: -507192000 | CK34: -3564012000 | CL34: -1094041000 | CM34: 611089000 | CN34: 600168000 | CO34: 597808000 | CP34: -2459012000 | CQ34: 10959000 | CT34: 2622000 | CU34: 8381000 | CV34: 10307000 | DD34: 2622000 | DE34: 8497000 | DF34: 10528000 | DJ34: 7278000 | DK34: 205940000 | DL34: 590676000 | DM34: 1962193000 | DN34: 2092975000 | DO34: 4004532000 | DP34: 1337982000 | EA34: 590676000 | EB34: 1962193000 | EC34: 2092975000 | ED34: 4011810000 | EE34: 1543922000 | EF34: 4149000 | EG34: 3297000 | EH34: 2731000 | EI34: 2804000 | EJ34: 2042000 | EK34: 16493000 | EL34: 14374000 | EM34: 10429000 | EN34: 16013000 | EY34: 640000 | FA34: 10000 | FE34: 1090000 | FF34: 420000 | FG34: 234000 | FH34: 11000 | FL34: 22000 | FM34: 1007000 | FN34: 11968000 | FO34: 1068000 | FP34: 70000 | FQ34: 5914000 | FR34: 1007000 | FS34: 2520937000 | FT34: 433000 | FU34: 341000 | FV34: 1368000 | FW34: 3046386000 | FX34: 43826000 | FY34: -4000 | FZ34: -3000 | GA34: 583000 | GB34: 2764000 | GC34: 2638000 | GD34: -10623000 | GE34: -10921000 | GF34: -2360000 | GG34: -3056820000 | GH34: 2469183000
A35: 34 | B35: ГУБАХАХЛЕБ, ООО | C35: 1025901778660 | D35: 32 | E35: Производство хлеба и мучных кондитерских изделий, тортов и пирожных недлительного хранения | H35: 33535 | I35: 1272361 | K35: 9225063 | L35: 9920667 | M35: 10363824 | N35: 12256848 | O35: 12540922 | P35: 17859000 | Q35: 18951000 | R35: 18439000 | S35: 7032000 | T35: 5000000 | AJ35: 19166000 | AK35: 20194000 | AL35: 19825000 | AM35: 8652000 | AN35: 13646000 | AO35: 17782000 | AP35: 23633000 | AQ35: 21195000 | AR35: 17384000 | AS35: 6572000 | AT35: 15230000 | AU35: 17533000 | AV35: 17823000 | AW35: 21236000 | AX35: 9860000 | BB35: 11840000 | BD35: 680000 | BE35: 531000 | BF35: 952000 | BG35: 4503000 | BH35: 5000 | BI35: 62000 | BJ35: 992000 | BK35: 1374000 | BL35: 1416000 | BM35: 1536000 | BN35: 33754000 | BO35: 42701000 | BP35: 41353000 | BQ35: 56517000 | BR35: 18023000 | BS35: 52920000 | BT35: 62895000 | BU35: 61178000 | BV35: 65169000 | BW35: 31669000 | BX35: 109000 | BY35: 109000 | BZ35: 109000 | CA35: 109000 | CB35: 109000 | CH35: 13319000 | CI35: 7503000 | CJ35: 11112000 | CK35: 20728000 | CL35: -10709000 | CM35: 13480000 | CN35: 7664000 | CO35: 19773000 | CP35: 20889000 | CQ35: -10548000 | CS35: 1000000 | CT35: 1000000 | DB35: 1251000 | DC35: 2251000 | DD35: 1251000 | DE35: -98000 | DG35: 17133000 | DH35: 21535000 | DI35: 20350000 | DK35: 600000 | DL35: 16644000 | DM35: 30308000 | DN35: 18827000 | DO35: 37492000 | DP35: 41617000 | DV35: 2274000 | DY35: 6886000 | EA35: 38189000 | EB35: 52980000 | EC35: 40154000 | ED35: 44378000 | EE35: 42217000 | EF35: 216598000 | EG35: 214968000 | EH35: 250085000 | EI35: 225730000 | EJ35: 196323000 | EK35: 157762000 | EL35: 156090000 | EM35: 168221000 | EN35: 151356000 | EO35: 127467000 | EP35: 50217000 | EQ35: 48146000 | ER35: 65227000 | ES35: 78154000 | ET35: 90199000 | EU35: 17516000 | EV35: 17876000 | EW35: 19346000 | EX35: 19516000 | EY35: 19123000 | FG35: 1676000 | FH35: 70000 | FJ35: 440000 | FK35: 402000 | FL35: 491000 | FO35: 208000 | FP35: 89000 | FQ35: 715000 | FR35: 37618000 | FS35: 5492000 | FT35: 652000 | FU35: 754000 | FV35: 2903000 | FW35: 13624000 | FX35: 1207000 | GA35: 463000 | GB35: -370000 | GC35: 7491000 | GD35: -9781000 | GE35: -8211000 | GF35: -3249000 | GG35: 398000 | GH35: -28690000
A36: 35 | B36: ГЭКОМ, ООО | C36: 1145958052371 | D36: 11 | E36: Производство пара и горячей воды (тепловой энергии) | F36: 2035788 | K36: 4131155 | L36: 1579268 | M36: 55237 | N36: 972978 | P36: 247619000 | Q36: 191808000 | R36: 139776000 | S36: 85782000 | T36: 18233000 | AE36: 33000 | AJ36: 263700000 | AK36: 235144000 | AL36: 214133000 | AM36: 174215000 | AN36: 159813000 | AO36: 1349000 | AP36: 6232000 | AQ36: 9154000 | AR36: 9551000 | AS36: 12243000 | AT36: 72924000 | AU36: 66020000 | AV36: 82965000 | AW36: 88021000 | AX36: 104238000 | BD36: 3456000 | BE36: 45000 | BF36: 451000 | BG36: 2317000 | BH36: 911000 | BI36: 37871000 | BJ36: 26517000 | BK36: 15063000 | BL36: 5207000 | BM36: 3070000 | BN36: 121042000 | BO36: 108948000 | BP36: 114679000 | BQ36: 117507000 | BR36: 123157000 | BS36: 384741000 | BT36: 344092000 | BU36: 328812000 | BV36: 291722000 | BW36: 282970000 | BX36: 20000 | BY36: 20000 | BZ36: 20000 | CA36: 20000 | CB36: 20000 | CH36: -44549000 | CI36: -147258000 | CJ36: -265903000 | CK36: -334990000 | CL36: -430391000 | CM36: -44529000 | CN36: -147238000 | CO36: -265883000 | CP36: -334970000 | CQ36: -430371000 | CW36: 209070000 | CX36: 138362000 | CY36: 69876000 | CZ36: 12514000 | DB36: 212195000 | DC36: 143281000 | DD36: 76325000 | DE36: 18331000 | DF36: 960000 | DG36: 60220000 | DH36: 49690000 | DI36: 50603000 | DJ36: 53670000 | DK36: 56738000 | DL36: 156856000 | DM36: 298359000 | DN36: 467767000 | DO36: 554691000 | DP36: 655643000 | EA36: 217076000 | EB36: 348049000 | EC36: 518370000 | ED36: 608361000 | EE36: 712381000 | EF36: 244739000 | EG36: 255891000 | EH36: 258582000 | EI36: 307611000 | EJ36: 324873000 | EK36: 274263000 | EL36: 308378000 | EM36: 326204000 | EN36: 339553000 | EO36: 347822000 | EU36: 33392000 | EV36: 41399000 | EW36: 47627000 | EX36: 27723000 | EY36: 26732000 | FE36: 2000 | FJ36: 2524000 | FK36: 3724000 | FL36: 3095000 | FM36: 3068000 | FN36: 3068000 | FO36: 2398000 | FP36: 10691000 | FQ36: 28236000 | FR36: 29873000 | FS36: 30007000 | FT36: 2600000 | FU36: 41244000 | FV36: 56149000 | FW36: 50585000 | FX36: 133445000 | FY36: 12932000 | FZ36: 25489000 | GA36: 29441000 | GB36: 14384000 | GC36: 58003000 | GD36: -52709000 | GE36: -102684000 | GF36: -116829000 | GG36: -69061000 | GH36: -98184000
A37: 36 | B37: ДАРХАН-РЭЙЛ, ООО | C37: 1195958007893 | D37: 6 | E37: Транспортная обработка грузов | F37: 1723843 | G37: 1260939 | I37: 616096 | J37: 274662 | K37: 7406228 | L37: 12603288 | M37: 8634950 | N37: 12941598 | O37: 4755802 | P37: 29698000 | Q37: 51507000 | R37: 34104000 | S37: 39432000 | T37: 133332000 | AB37: 3000 | AJ37: 29698000 | AK37: 51507000 | AL37: 34107000 | AM37: 39432000 | AN37: 133332000 | AO37: 505000 | AP37: 104000 | AQ37: 94000 | AR37: 48000 | AS37: 210000 | AT37: 12233000 | AU37: 13023000 | AV37: 20933000 | AW37: 24929000 | AX37: 24759000 | BD37: 277000 | BE37: 265000 | BF37: 373000 | BG37: 75000 | BH37: 893000 | BI37: 3534000 | BJ37: 7465000 | BK37: 772000 | BL37: 224000 | BM37: 67000 | BN37: 16575000 | BO37: 20868000 | BP37: 22172000 | BQ37: 25276000 | BR37: 25929000 | BS37: 46273000 | BT37: 72375000 | BU37: 56279000 | BV37: 64708000 | BW37: 159261000 | BX37: 300000 | BY37: 750000 | BZ37: 750000 | CA37: 750000 | CB37: 750000 | CH37: 5348000 | CI37: -140000 | CJ37: -7968000 | CK37: -5172000 | CL37: 9954000 | CM37: 5648000 | CN37: 610000 | CO37: -7218000 | CP37: -4422000 | CQ37: 10704000 | CV37: 9387000 | CW37: 16576000 | CX37: 43844000 | CY37: 30944000 | CZ37: 30519000 | DA37: 125891000 | DB37: 16576000 | DC37: 43844000 | DD37: 30944000 | DE37: 30519000 | DF37: 135278000 | DG37: 14395000 | DH37: 19196000 | DI37: 16301000 | DJ37: 17438000 | DK37: 5291000 | DL37: 9652000 | DM37: 8726000 | DN37: 15209000 | DO37: 19488000 | DP37: 6303000 | EA37: 24048000 | EB37: 27921000 | EC37: 32553000 | ED37: 38611000 | EE37: 13279000 | EF37: 132408000 | EG37: 127412000 | EH37: 125394000 | EI37: 107752000 | EJ37: 147259000 | EK37: 89138000 | EL37: 97109000 | EM37: 106792000 | EN37: 90610000 | EO37: 117854000 | EU37: 29341000 | EV37: 33830000 | EW37: 16114000 | EX37: 13149000 | EY37: 24971000 | FH37: 108000 | FJ37: 963000 | FK37: 1175000 | FL37: 1323000 | FM37: 2638000 | FN37: 1982000 | FO37: 11000 | FP37: 5139000 | FQ37: 7931000 | FR37: 2932000 | FS37: 20041000 | FT37: 1312000 | FU37: 5942000 | FV37: 17064000 | FW37: 6916000 | FX37: 5767000 | FY37: -1783000 | GB37: -275000 | GC37: -1677000 | GD37: 9882000 | GE37: -5505000 | GF37: -7968000 | GG37: -2796000 | GH37: 15049000
A38: 37 | B38: ДЕРЖАВА, ООО | C38: 1125948000870 | D38: 13 | E38: Деятельность сухопутного пассажирского транспорта: перевозки пассажиров в городском и пригородном сообщении | F38: 3564 | G38: 202585 | K38: 3621 | L38: 56155 | P38: 35544000 | AJ38: 35544000 | AO38: 569000 | AT38: 7337000 | AY38: 480000 | BD38: 1000 | BI38: 4408000 | BN38: 13730000 | BS38: 49274000 | BX38: 10000 | CC38: 10694000 | CH38: 97000 | CM38: 10801000 | CR38: 873000 | CW38: 25086000 | DB38: 25959000 | DG38: 1000 | DL38: 12513000 | EA38: 12514000 | EF38: 19487000 | EK38: 19039000 | FO38: 1885000 | FT38: 1811000 | FY38: -27000 | GD38: 495000
A39: 38 | B39: ДИЛ-БАНК (ООО) | C39: 1027739007218 | D39: 23 | E39: Денежное посредничество прочее
A40: 39 | B40: ДОМ НА НОРИЛЬСКОЙ, ЖСК | C40: 1155958079023 | D40: 10 | E40: Управление эксплуатацией жилого фонда за вознаграждение или на договорной основе | Q40: 39744000 | R40: 39744000 | AK40: 39744000 | AL40: 39744000 | AO40: 34616000 | AT40: 13496000 | AU40: 13496000 | AV40: 12511000 | AW40: 12511000 | AX40: 12511000 | BN40: 48112000 | BO40: 13496000 | BP40: 12511000 | BQ40: 12511000 | BR40: 12511000 | BS40: 48112000 | BT40: 53240000 | BU40: 52255000 | BV40: 12511000 | BW40: 12511000 | CD40: 5128000 | CH40: -87698000 | CI40: -83796000 | CJ40: -221452000 | CK40: -261792000 | CL40: -261792000 | CM40: 41558000 | CN40: 48298000 | CO40: 50432000 | CP40: 10095000 | CQ40: 9801000 | DL40: 6554000 | DM40: 4563000 | DW40: 379000 | DX40: 1823000 | DY40: 2416000 | DZ40: 2710000 | EA40: 6554000 | EB40: 4942000 | EC40: 1823000 | ED40: 2416000 | EE40: 2710000 | FP40: 3902000 | FV40: 144918000 | FW40: 40340000 | GE40: 3902000 | GF40: -144918000 | GG40: -40340000
...

Sheet Лист2
A3: Названия строк | B3: Количество по полю Вид деятельности/отрасль
A4: Аренда и лизинг грузовых транспортных средств | B4: 1
A5: Аренда и лизинг сельскохозяйственных машин и оборудования | B5: 1
A6: Аренда и управление собственным или арендованным недвижимым имуществом | B6: 2
A7: Аренда и управление собственным или арендованным нежилым недвижимым имуществом | B7: 1
A8: Денежное посредничество прочее | B8: 13
A9: Деятельность автомобильного грузового транспорта | B9: 2
A10: Деятельность автомобильного грузового транспорта и услуги по перевозкам | B10: 3
A11: Деятельность агентов по оптовой торговле радио- и телеаппаратурой, техническими носителями информации | B11: 1
A12: Деятельность агентов по оптовой торговле строительными материалами | B12: 1
A13: Деятельность административно-хозяйственная комплексная по обеспечению работы организации | B13: 1
A14: Деятельность в области архитектуры, инженерных изысканий и предоставление технических консультаций в этих областях | B14: 1
A15: Деятельность в области архитектуры, связанная с созданием архитектурного объекта | B15: 1
... A133: Общий итог | B133: 252

Sheet Выборка 1
A1: № | B1: Возраст компании, лет | C1: Вид деятельности/отрасль | D1: 2020, Основные средства , RUB | E1: 2021, Основные средства , RUB | F1: 2022, Основные средства , RUB | G1: 2023, Основные средства , RUB | H1: 2024, Основные средства , RUB | I1: 2020, Запасы, RUB | J1: 2021, Запасы, RUB | K1: 2022, Запасы, RUB | L1: 2023, Запасы, RUB | M1: 2024, Запасы, RUB | N1: 2020, Дебиторская задолженность, RUB | O1: 2021, Дебиторская задолженность, RUB | P1: 2022, Дебиторская задолженность, RUB | Q1: 2023, Дебиторская задолженность, RUB | R1: 2024, Дебиторская задолженность, RUB | S1: 2020, Денежные средства и денежные эквиваленты, RUB | T1: 2021, Денежные средства и денежные эквиваленты, RUB | U1: 2022, Денежные средства и денежные эквиваленты, RUB | V1: 2023, Денежные средства и денежные эквиваленты, RUB | W1: 2024, Денежные средства и денежные эквиваленты, RUB | X1: 2020, Нераспределенная прибыль (непокрытый убыток), RUB | Y1: 2021, Нераспределенная прибыль (непокрытый убыток), RUB | Z1: 2022, Нераспределенная прибыль (непокрытый убыток), RUB | AA1: 2023, Нераспределенная прибыль (непокрытый убыток), RUB | AB1: 2024, Нераспределенная прибыль (непокрытый убыток), RUB | AC1: 2020, Заёмные средства (краткосрочные), RUB | AD1: 2021, Заёмные средства (краткосрочные), RUB | AE1: 2022, Заёмные средства (краткосрочные), RUB | AF1: 2023, Заёмные средства (краткосрочные), RUB | AG1: 2024, Заёмные средства (краткосрочные), RUB | AH1: 2020, Кредиторская задолженность, RUB | AI1: 2021, Кредиторская задолженность, RUB | AJ1: 2022, Кредиторская задолженность, RUB | AK1: 2023, Кредиторская задолженность, RUB | AL1: 2024, Кредиторская задолженность, RUB | AM1: 2020, Выручка, RUB | AN1: 2021, Выручка, RUB | AO1: 2022, Выручка, RUB | AP1: 2023, Выручка, RUB | AQ1: 2024, Выручка, RUB | AR1: 2020, Себестоимость продаж, RUB | AS1: 2021, Себестоимость продаж, RUB | AT1: 2022, Себестоимость продаж, RUB | AU1: 2023, Себестоимость продаж, RUB | AV1: 2024, Себестоимость продаж, RUB | AW1: 2020, Коммерческие расходы, RUB | AX1: 2021, Коммерческие расходы, RUB | AY1: 2022, Коммерческие расходы, RUB | AZ1: 2023, Коммерческие расходы, RUB | BA1: 2024, Коммерческие расходы, RUB | BB1: 2020, Управленческие расходы, RUB | BC1: 2021, Управленческие расходы, RUB | BD1: 2022, Управленческие расходы, RUB | BE1: 2023, Управленческие расходы, RUB | BF1: 2024, Управленческие расходы, RUB | BG1: 2020, Прочие доходы, RUB | BH1: 2021, Прочие доходы, RUB | BI1: 2022, Прочие доходы, RUB | BJ1: 2023, Прочие доходы, RUB | BK1: 2024, Прочие доходы, RUB | BL1: 2020, Прочие расходы, RUB | BM1: 2021, Прочие расходы, RUB | BN1: 2022, Прочие расходы, RUB | BO1: 2023, Прочие расходы, RUB | BP1: 2024, Прочие расходы, RUB | BQ1: 2020, Чистая прибыль (убыток), RUB | BR1: 2021, Чистая прибыль (убыток), RUB | BS1: 2022, Чистая прибыль (убыток), RUB | BT1: 2023, Чистая прибыль (убыток), RUB | BU1: 2024, Чистая прибыль (убыток), RUB
A2: 211 | B2: 12 | C2: Управление эксплуатацией нежилого фонда за вознаграждение или на договорной основе | N2: 3679000 | O2: 4504000 | P2: 4254000 | Q2: 3207000 | R2: 2934000 | S2: 530000 | T2: 692000 | U2: 538000 | V2: 501000 | W2: 1000 | AC2: 2145000 | AI2: 45000 | AJ2: 62000 | AK2: 58000 | AL2: 58000 | AM2: 10962000 | AN2: 14691000 | AO2: 1920000 | AP2: 1612000 | AR2: 9598000 | AS2: 10237000 | AT2: 1974000 | AU2: 2505000 | AV2: 279000 | BG2: 27000 | BH2: 6000 | BI2: 7000 | BJ2: 11000 | BL2: 258000 | BM2: 130000 | BN2: 270000 | BO2: 56000 | BP2: 9000 | BQ2: 1133000 | BR2: 3826000 | BS2: -420000 | BT2: -1064000 | BU2: -795000
A3: 7 | B3: 17 | C3: Управление эксплуатацией жилого фонда за вознаграждение или на договорной основе | D3: 1496000 | E3: 7205000 | F3: 6909000 | I3: 2205000 | J3: 608000 | K3: 500000 | L3: 233000 | M3: 233000 | N3: 38472000 | O3: 14456000 | P3: 7610000 | Q3: 17806000 | R3: 14298000 | S3: 17451000 | T3: 12106000 | U3: 1009000 | V3: 307000 | W3: 1062000 | X3: 25831000 | Y3: -2719000 | Z3: -9356000 | AA3: 6816000 | AB3: -722000 | AH3: 13228000 | AI3: 25791000 | AJ3: 24330000 | AK3: 11515000 | AL3: 16300000 | AM3: 111609000 | AN3: 32742000 | AO3: 7778000 | AP3: 3700000 | AR3: 94923000 | AS3: 28040000 | AT3: 15221000 | AU3: 11887000 | AV3: 688000 | BG3: 168000 | BH3: 1626000 | BI3: 2486000 | BJ3: 19356000 | BK3: 11000 | BL3: 596000 | BM3: 26201000 | BN3: 545000 | BO3: 8256000 | BP3: 6749000 | BQ3: 14845000 | BR3: -20960000 | BS3: -5625000 | BT3: 2790000 | BU3: -7539000
